Workbook

Sheet conditional statement
A1: Employee_ID | B1: Name | C1: Department | D1: Gender | E1: Age | F1: Attendance_% | G1: Score | H1: Sales_Amount | I1: Experience_Years | J1: Attendance status | K1: Pass/Fail | L1: Sales person check | M1: Bonus eligibility | N1: High performer | O1: Young or experience | P1: Performance Rating | Q1: Sales Incentive | R1: Promotion Eligiblity | S1: Work Mode | T1: Salary Hike Decision
A2: E001 | B2: Anu | C2: HR | D2: F | E2: 25 | F2: 92 | G2: 78 | H2: 0 | I2: 2 | J2: =IF(F2>=75,"Present","Absent") -> Present | K2: =IF(G2>=50,"Pass","Fail") -> Pass | L2: =IF(C2="Sales","Yes","NO") -> NO | M2: =IF(C2="Sales",IF( H2>=40000,"ELIGIBLE","Not Eligible"),"NOT ELIGIBLE") -> NOT ELIGIBLE | N2: =IF(G2>=80,IF(F2>=90,"High Performer","Normal"),"Normal") -> Normal | O2: =IF(OR(E2<30,I2>=10),"SPECIAL CATEGORY","REGULAR") -> SPECIAL CATEGORY | P2: =IF(G2>=85,"Excellent",IF(G2>=70,"Good",IF(G2>=50,"Average","Poor"))) -> Good | Q2: =IF(H2>=50000,"50% incentive",IF(H2>=30000,"10% incentive",IF(H2>0,"2% incentive","No Incentive"))) -> No Incentive | R2: =IF(AND(F2>=85,G2>=75,I2>=5),"Eligible","Not Eligible") -> Not Eligible | S2: =IF(F2>=90,"WFH",IF(F2>=75,"WFO","Warning")) -> WFH | T2: =IF(P2="Excellent","15% Hike",IF(P2="Good","10% Hike",IF(P2="Average","5% Hike","No Hike"))) -> 10% Hike
A3: E002 | B3: Ravi | C3: Sales | D3: M | E3: 32 | F3: 85 | G3: 65 | H3: 45000 | I3: 6 | J3: =IF(F3>=75,"Present","Absent") -> Present | K3: =IF(G3>=50,"Pass","Fail") -> Pass | L3: =IF(C3="Sales","Yes","NO") -> Yes | M3: =IF(C3="Sales",IF( H3>=40000,"ELIGIBLE","Not Eligible"),"NOT ELIGIBLE") -> ELIGIBLE | N3: =IF(G3>=80,IF(F3>=90,"High Performer","Normal"),"Normal") -> Normal | O3: =IF(OR(E3<30,I3>=10),"SPECIAL CATEGORY","REGULAR") -> REGULAR | P3: =IF(G3>=85,"Excellent",IF(G3>=70,"Good",IF(G3>=50,"Average","Poor"))) -> Average | Q3: =IF(H3>=50000,"50% incentive",IF(H3>=30000,"10% incentive",IF(H3>0,"2% incentive","No Incentive"))) -> 10% incentive | R3: =IF(AND(F3>=85,G3>=75,I3>=5),"Eligible","Not Eligible") -> Not Eligible | S3: =IF(F3>=90,"WFH",IF(F3>=75,"WFO","Warning")) -> WFO | T3: =IF(P3="Excellent","15% Hike",IF(P3="Good","10% Hike",IF(P3="Average","5% Hike","No Hike"))) -> 5% Hike
A4: E003 | B4: Karthik | C4: IT | D4: M | E4: 28 | F4: 96 | G4: 88 | H4: 0 | I4: 4 | J4: =IF(F4>=75,"Present","Absent") -> Present | K4: =IF(G4>=50,"Pass","Fail") -> Pass | L4: =IF(C4="Sales","Yes","NO") -> NO | M4: =IF(C4="Sales",IF( H4>=40000,"Eligible","Not Eligible"),"NOT ELIGIBLE") -> NOT ELIGIBLE | N4: =IF(G4>=80,IF(F4>=90,"High Performer","Normal"),"Normal") -> High Performer | O4: =IF(OR(E4<30,I4>=10),"SPECIAL CATEGORY","REGULAR") -> SPECIAL CATEGORY | P4: =IF(G4>=85,"Excellent",IF(G4>=70,"Good",IF(G4>=50,"Average","Poor"))) -> Excellent | Q4: =IF(H4>=50000,"50% incentive",IF(H4>=30000,"10% incentive",IF(H4>0,"2% incentive","No Incentive"))) -> No Incentive | R4: =IF(AND(F4>=85,G4>=75,I4>=5),"Eligible","Not Eligible") -> Not Eligible | S4: =IF(F4>=90,"WFH",IF(F4>=75,"WFO","Warning")) -> WFH | T4: =IF(P4="Excellent","15% Hike",IF(P4="Good","10% Hike",IF(P4="Average","5% Hike","No Hike"))) -> 15% Hike
A5: E004 | B5: Priya | C5: Sales | D5: F | E5: 29 | F5: 70 | G5: 55 | H5: 30000 | I5: 3 | J5: =IF(F5>=75,"Present","Absent") -> Absent | K5: =IF(G5>=50,"Pass","Fail") -> Pass | L5: =IF(C5="Sales","Yes","NO") -> Yes | N5: =IF(G5>=80,IF(F5>=90,"High Performer","Normal"),"Normal") -> Normal | O5: =IF(OR(E5<30,I5>=10),"SPECIAL CATEGORY","REGULAR") -> SPECIAL CATEGORY | P5: =IF(G5>=85,"Excellent",IF(G5>=70,"Good",IF(G5>=50,"Average","Poor"))) -> Average | Q5: =IF(H5>=50000,"50% incentive",IF(H5>=30000,"10% incentive",IF(H5>0,"2% incentive","No Incentive"))) -> 10% incentive | R5: =IF(AND(F5>=85,G5>=75,I5>=5),"Eligible","Not Eligible") -> Not Eligible | S5: =IF(F5>=90,"WFH",IF(F5>=75,"WFO","Warning")) -> Warning | T5: =IF(P5="Excellent","15% Hike",IF(P5="Good","10% Hike",IF(P5="Average","5% Hike","No Hike"))) -> 5% Hike
A6: E005 | B6: Suresh | C6: Finance | D6: M | E6: 45 | F6: 88 | G6: 72 | H6: 0 | I6: 18 | J6: =IF(F6>=75,"Present","Absent") -> Present | K6: =IF(G6>=50,"Pass","Fail") -> Pass | L6: =IF(C6="Sales","Yes","NO") -> NO | M6: =IF(C6="Sales",IF( H6>=40000,"Eligible","Not Eligible"),"NOT ELIGIBLE") -> NOT ELIGIBLE | N6: =IF(G6>=80,IF(F6>=90,"High Performer","Normal"),"Normal") -> Normal | O6: =IF(OR(E6<30,I6>=10),"SPECIAL CATEGORY","REGULAR") -> SPECIAL CATEGORY | P6: =IF(G6>=85,"Excellent",IF(G6>=70,"Good",IF(G6>=50,"Average","Poor"))) -> Good | Q6: =IF(H6>=50000,"50% incentive",IF(H6>=30000,"10% incentive",IF(H6>0,"2% incentive","No Incentive"))) -> No Incentive | R6: =IF(AND(F6>=85,G6>=75,I6>=5),"Eligible","Not Eligible") -> Not Eligible | S6: =IF(F6>=90,"WFH",IF(F6>=75,"WFO","Warning")) -> WFO | T6: =IF(P6="Excellent","15% Hike",IF(P6="Good","10% Hike",IF(P6="Average","5% Hike","No Hike"))) -> 10% Hike
A7: E006 | B7: Meena | C7: Sales | D7: F | E7: 35 | F7: 91 | G7: 82 | H7: 60000 | I7: 10 | J7: =IF(F7>=75,"Present","Absent") -> Present | K7: =IF(G7>=50,"Pass","Fail") -> Pass | L7: =IF(C7="Sales","Yes","NO") -> Yes | M7: =IF(C7="Sales",IF( H7>=40000,"Eligible","Not Eligible"),"NOT ELIGIBLE") -> Eligible | N7: =IF(G7>=80,IF(F7>=90,"High Performer","Normal"),"Normal") -> High Performer | O7: =IF(OR(E7<30,I7>=10),"SPECIAL CATEGORY","REGULAR") -> SPECIAL CATEGORY | P7: =IF(G7>=85,"Excellent",IF(G7>=70,"Good",IF(G7>=50,"Average","Poor"))) -> Good | Q7: =IF(H7>=50000,"50% incentive",IF(H7>=30000,"10% incentive",IF(H7>0,"2% incentive","No Incentive"))) -> 50% incentive | R7: =IF(AND(F7>=85,G7>=75,I7>=5),"Eligible","Not Eligible") -> Eligible | S7: =IF(F7>=90,"WFH",IF(F7>=75,"WFO","Warning")) -> WFH | T7: =IF(P7="Excellent","15% Hike",IF(P7="Good","10% Hike",IF(P7="Average","5% Hike","No Hike"))) -> 10% Hike
A8: E007 | B8: Arjun | C8: IT | D8: M | E8: 24 | F8: 60 | G8: 40 | H8: 0 | I8: 1 | J8: =IF(F8>=75,"Present","Absent") -> Absent | K8: =IF(G8>=50,"Pass","Fail") -> Fail | L8: =IF(C8="Sales","Yes","NO") -> NO | M8: =IF(C8="Sales",IF( H8>=40000,"Eligible","Not Eligible"),"NOT ELIGIBLE") -> NOT ELIGIBLE | N8: =IF(G8>=80,IF(F8>=90,"High Performer","Normal"),"Normal") -> Normal | O8: =IF(OR(E8<30,I8>=10),"SPECIAL CATEGORY","REGULAR") -> SPECIAL CATEGORY | P8: =IF(G8>=85,"Excellent",IF(G8>=70,"Good",IF(G8>=50,"Average","Poor"))) -> Poor | Q8: =IF(H8>=50000,"50% incentive",IF(H8>=30000,"10% incentive",IF(H8>0,"2% incentive","No Incentive"))) -> No Incentive | R8: =IF(AND(F8>=85,G8>=75,I8>=5),"Eligible","Not Eligible") -> Not Eligible | S8: =IF(F8>=90,"WFH",IF(F8>=75,"WFO","Warning")) -> Warning | T8: =IF(P8="Excellent","15% Hike",IF(P8="Good","10% Hike",IF(P8="Average","5% Hike","No Hike"))) -> No Hike
A9: E008 | B9: Kavya | C9: HR | D9: F | E9: 31 | F9: 95 | G9: 90 | H9: 0 | I9: 7 | J9: =IF(F9>=75,"Present","Absent") -> Present | K9: =IF(G9>=50,"Pass","Fail") -> Pass | L9: =IF(C9="Sales","Yes","NO") -> NO | M9: =IF(C9="Sales",IF( H9>=40000,"Eligible","Not Eligible"),"NOT ELIGIBLE") -> NOT ELIGIBLE | N9: =IF(G9>=80,IF(F9>=90,"High Performer","Normal"),"Normal") -> High Performer | O9: =IF(OR(E9<30,I9>=10),"SPECIAL CATEGORY","REGULAR") -> REGULAR | P9: =IF(G9>=85,"Excellent",IF(G9>=70,"Good",IF(G9>=50,"Average","Poor"))) -> Excellent | Q9: =IF(H9>=50000,"50% incentive",IF(H9>=30000,"10% incentive",IF(H9>0,"2% incentive","No Incentive"))) -> No Incentive | R9: =IF(AND(F9>=85,G9>=75,I9>=5),"Eligible","Not Eligible") -> Eligible | S9: =IF(F9>=90,"WFH",IF(F9>=75,"WFO","Warning")) -> WFH | T9: =IF(P9="Excellent","15% Hike",IF(P9="Good","10% Hike",IF(P9="Average","5% Hike","No Hike"))) -> 15% Hike
A10: E009 | B10: Bala | C10: Sales | D10: M | E10: 27 | F10: 89 | G10: 68 | H10: 38000 | I10: 4 | J10: =IF(F10>=75,"Present","Absent") -> Present | K10: =IF(G10>=50,"Pass","Fail") -> Pass | L10: =IF(C10="Sales","Yes","NO") -> Yes | M10: =IF(C10="Sales",IF( H10>=40000,"Eligible","Not Eligible"),"NOT ELIGIBLE") -> Not Eligible | N10: =IF(G10>=80,IF(F10>=90,"High Performer","Normal"),"Normal") -> Normal | O10: =IF(OR(E10<30,I10>=10),"SPECIAL CATEGORY","REGULAR") -> SPECIAL CATEGORY | P10: =IF(G10>=85,"Excellent",IF(G10>=70,"Good",IF(G10>=50,"Average","Poor"))) -> Average | Q10: =IF(H10>=50000,"50% incentive",IF(H10>=30000,"10% incentive",IF(H10>0,"2% incentive","No Incentive"))) -> 10% incentive | R10: =IF(AND(F10>=85,G10>=75,I10>=5),"Eligible","Not Eligible") -> Not Eligible | S10: =IF(F10>=90,"WFH",IF(F10>=75,"WFO","Warning")) -> WFO | T10: =IF(P10="Excellent","15% Hike",IF(P10="Good","10% Hike",IF(P10="Average","5% Hike","No Hike"))) -> 5% Hike
A11: E010 | B11: Divya | C11: Finance | D11: F | E11: 41 | F11: 76 | G11: 58 | H11: 0 | I11: 15 | J11: =IF(F11>=75,"Present","Absent") -> Present | K11: =IF(G11>=50,"Pass","Fail") -> Pass | L11: =IF(C11="Sales","Yes","NO") -> NO | M11: =IF(C11="Sales",IF( H11>=40000,"Eligible","Not Eligible"),"NOT ELIGIBLE") -> NOT ELIGIBLE | N11: =IF(G11>=80,IF(F11>=90,"High Performer","Normal"),"Normal") -> Normal | O11: =IF(OR(E11<30,I11>=10),"SPECIAL CATEGORY","REGULAR") -> SPECIAL CATEGORY | P11: =IF(G11>=85,"Excellent",IF(G11>=70,"Good",IF(G11>=50,"Average","Poor"))) -> Average | Q11: =IF(H11>=50000,"50% incentive",IF(H11>=30000,"10% incentive",IF(H11>0,"2% incentive","No Incentive"))) -> No Incentive | R11: =IF(AND(F11>=85,G11>=75,I11>=5),"Eligible","Not Eligible") -> Not Eligible | S11: =IF(F11>=90,"WFH",IF(F11>=75,"WFO","Warning")) -> WFO | T11: =IF(P11="Excellent","15% Hike",IF(P11="Good","10% Hike",IF(P11="Average","5% Hike","No Hike"))) -> 5% Hike
T12: =IF(P12="Excellent","15% Hike",IF(P12="Good","10% Hike",IF(P12="Average","5% Hike","No Hike"))) -> No Hike
A14: Level 1: Basic IF | C14: Level 2: IF with AND / OR
A16: Attendance Status | C16: 4. Bonus Eligibility
A18: If Attendance_% ≥ 75 → "Present"
A20: Else → "Absent" | C20: Eligible if:
A22: Pass / Fail
A24: If Score ≥ 50 → "Pass" | C24: Department = Sales AND
A26: Else → "Fail" | C26: Sales_Amount ≥ 40000
A28: Sales Person Check | C28: Else "Not Eligible"
A30: If Department = "Sales" → "Yes" | C30: 5. High Performer
A32: Else → "No"
C34: If Score ≥ 80 AND Attendance_% ≥ 90
C36: Output "High Performer" else "Normal"
C38: 6. Young or Experienced
C42: If Age < 30 OR Experience_Years ≥ 10
C44: Output "Special Category" else "Regular"
A47: Level 3: Nested IF | C47: Level 4: Real-World Logic (Interview Level) | I47: Bonus Challenge (Very Important for Interviews)
A49: 7. Performance Rating | C49: 9. Promotion Eligibility | I49: 11. Salary Hike Decision
I51: If Performance = "Excellent" → "15% Hike"
A53: Score ≥ 85 → "Excellent" | C53: Experience ≥ 5 AND | I53: If "Good" → "10% Hike"
A55: Score ≥ 70 → "Good" | C55: Score ≥ 75 AND | I55: If "Average" → "5% Hike"
A57: Score ≥ 50 → "Average" | C57: Attendance ≥ 85 | I57: Else → "No Hike"
A59: Else → "Poor" | C59: Output "Eligible" / "Not Eligible" | I59: (Use the Performance Rating column you created earlier)
A61: 8. Sales Incentive | C61: 10. Work Mode
C63: If Attendance_% ≥ 90 → "WFH Eligible"
A65: Sales ≥ 50000 → "10% Incentive" | C65: Else if Attendance_% ≥ 75 → "Office"
A67: Sales ≥ 30000 → "5% Incentive" | C67: Else → "Warning"
A69: Sales > 0 → "2% Incentive"
A71: Else → "No Incentive"
...

Sheet data cleaning
A1: A (Emp_ID) | B1: B (Full_Name) | C1: C (Email) | D1: D (Department_Code) | E1: E (Joining_Date) | F1: F (Status) | G1: G (Salary_Text) | H1: H (Remarks)
A2: EMP-001 | B2: Anu Devi | C2: anu.hr@company.com | D2: HR-IND | E2: 44727 | F2: Active | G2: ₹ 45,000 | H2: Good performer | I2: =IF(AND(F2="Active", E2<DATE(2022,1,1)), "Eligible", "Not Eligible") -> Not Eligible | J2: =IF(OR(F2="Inactive",H2="Late"),"Review needed","NO need") -> NO need | K2: =IF(RIGHT(D2,3)="IND", "India Employee", "Overseas") -> India Employee | L2: =LEFT(D2, FIND("-", D2) - 1) -> HR | M2: =LEFT(C2,FIND("@company.com",C2)-1) -> anu.hr | N2: =LEFT(A2,3) -> EMP | O2: =RIGHT(D2,3) -> IND | P2: =RIGHT(D2,FIND("-",D2)) -> IND | R2: =RIGHT(A2,3) -> 001 | S2: =LOWER(CONCATENATE(B2,".",L2,"@company.com")) -> anu devi.hr@company.com | V2: =_xlfn.CONCAT(A2,"|",D2) -> EMP-001|HR-IND | W2: =_xlfn.TEXTJOIN("-",TRUE,A2,B2,F2) -> EMP-001-Anu Devi-Active | Z2: =_xlfn.TEXTJOIN("/",TRUE,L2,O2,F2) -> HR/IND/Active | AB2: =TRIM(H2) -> Good performer | AD2: =SUBSTITUTE(SUBSTITUTE(G2,"₹",""),",","")*1 -> 45000 | AE2: =IF(AND(G2>60000,F2="Active"),"High Salary") -> High Salary
A3: EMP-002 | B3: Ravi Kumar | C3: ravi.sales@company.com | D3: SALES-USA | E3: 44256 | F3: Active | G3: ₹ 60,500 | H3: Late submission | I3: =IF(AND(F3="Active", E3<DATE(2022,1,1)), "Eligible", "Not Eligible") -> Eligible | J3: =IF(OR(F3="Inactive",H3="Late"),"Review needed","NO need") -> NO need | K3: =IF(RIGHT(D3,3)="IND", "India Employee", "Overseas") -> Overseas | L3: =LEFT(D3, FIND("-", D3) - 1) -> SALES | M3: =LEFT(C3,FIND("@company.com",C3)-1) -> ravi.sales | N3: =LEFT(A3,3) -> EMP | O3: =RIGHT(D3,3) -> USA | P3: =RIGHT(D3,FIND("-",D3)-3) -> USA | R3: =RIGHT(A3,3) -> 002 | S3: =LOWER(CONCATENATE(B3,".",L3,"@company.com")) -> ravi kumar.sales@company.com | V3: =_xlfn.CONCAT(A3,"|",D3) -> EMP-002|SALES-USA | W3: =_xlfn.TEXTJOIN("-",TRUE,A3,B3,F3) -> EMP-002-Ravi Kumar-Active | Z3: =_xlfn.TEXTJOIN("/",TRUE,L3,O3,F3) -> SALES/USA/Active | AB3: =TRIM(H3) -> Late submission | AD3: =SUBSTITUTE(SUBSTITUTE(G3,"₹",""),",","")*1 -> 60500 | AE3: =IF(AND(G3>60000,F3="Active"),"High Salary") -> High Salary
A4: EMP-003 | B4: Karthik R | C4: karthik.it@company.com | D4: IT-IND | E4: 45189 | F4: Inactive | G4: ₹ 38,000 | H4: Needs improvement | I4: =IF(AND(F4="Active", E4<DATE(2022,1,1)), "Eligible", "Not Eligible") -> Not Eligible | J4: =IF(OR(F4="Inactive",H4="Late"),"Review needed","NO need") -> Review needed | K4: =IF(RIGHT(D4,3)="IND", "India Employee", "Overseas") -> India Employee | L4: =LEFT(D4, FIND("-", D4) - 1) -> IT | M4: =LEFT(C4,FIND("@company.com",C4)-1) -> karthik.it | N4: =LEFT(A4,3) -> EMP | O4: =RIGHT(D4,3) -> IND | P4: =RIGHT(D4,FIND("-",D4)) -> IND | R4: =RIGHT(A4,3) -> 003 | S4: =LOWER(CONCATENATE(B4,".",L4,"@company.com")) -> karthik r.it@company.com | V4: =_xlfn.CONCAT(A4,"|",D4) -> EMP-003|IT-IND | W4: =_xlfn.TEXTJOIN("-",TRUE,A4,B4,F4) -> EMP-003-Karthik R-Inactive | Z4: =_xlfn.TEXTJOIN("/",TRUE,L4,O4,F4) -> IT/IND/Inactive | AB4: =TRIM(H4) -> Needs improvement | AD4: =SUBSTITUTE(SUBSTITUTE(G4,"₹",""),",","")*1 -> 38000 | AE4: =IF(AND(G4>60000,F4="Active"),"High Salary") -> FALSE
A5: EMP-004 | B5: Priya S | C5: priya.sales@company.com | D5: SALES-IND | E5: 44115 | F5: Active | G5: ₹ 72,000 | H5: Excellent | I5: =IF(AND(F5="Active", E5<DATE(2022,1,1)), "Eligible", "Not Eligible") -> Eligible | J5: =IF(OR(F5="Inactive",H5="Late"),"Review needed","NO need") -> NO need | K5: =IF(RIGHT(D5,3)="IND", "India Employee", "Overseas") -> India Employee | L5: =LEFT(D5, FIND("-", D5) - 1) -> SALES | M5: =LEFT(C5,FIND("@company.com",C5)-1) -> priya.sales | N5: =LEFT(A5,3) -> EMP | O5: =RIGHT(D5,3) -> IND | P5: =RIGHT(D5,FIND("-",D5)-3) -> IND | R5: =RIGHT(A5,3) -> 004 | S5: =LOWER(CONCATENATE(B5,".",L5,"@company.com")) -> priya s.sales@company.com | V5: =_xlfn.CONCAT(A5,"|",D5) -> EMP-004|SALES-IND | W5: =_xlfn.TEXTJOIN("-",TRUE,A5,B5,F5) -> EMP-004-Priya S-Active | Z5: =_xlfn.TEXTJOIN("/",TRUE,L5,O5,F5) -> SALES/IND/Active | AB5: =TRIM(H5) -> Excellent | AD5: =SUBSTITUTE(SUBSTITUTE(G5,"₹",""),",","")*1 -> 72000 | AE5: =IF(AND(G5>60000,F5="Active"),"High Salary") -> High Salary
A6: EMP-005 | B6: Suresh M | C6: suresh.fin@company.com | D6: FIN-USA | E6: 43467 | F6: Active | G6: ₹ 90,000 | H6: Senior staff | I6: =IF(AND(F6="Active", E6<DATE(2022,1,1)), "Eligible", "Not Eligible") -> Eligible | J6: =IF(OR(F6="Inactive",H6="Late"),"Review needed","NO need") -> NO need | K6: =IF(RIGHT(D6,3)="IND", "India Employee", "Overseas") -> Overseas | L6: =LEFT(D6, FIND("-", D6) - 1) -> FIN | M6: =LEFT(C6,FIND("@company.com",C6)-1) -> suresh.fin | N6: =LEFT(A6,3) -> EMP | O6: =RIGHT(D6,3) -> USA | P6: =RIGHT(D6,FIND("-",D6)-1) -> USA | R6: =RIGHT(A6,3) -> 005 | S6: =LOWER(CONCATENATE(B6,".",L6,"@company.com")) -> suresh m.fin@company.com | V6: =_xlfn.CONCAT(A6,"|",D6) -> EMP-005|FIN-USA | W6: =_xlfn.TEXTJOIN("-",TRUE,A6,B6,F6) -> EMP-005-Suresh M-Active | Z6: =_xlfn.TEXTJOIN("/",TRUE,L6,O6,F6) -> FIN/USA/Active | AB6: =TRIM(H6) -> Senior staff | AD6: =SUBSTITUTE(SUBSTITUTE(G6,"₹",""),",","")*1 -> 90000 | AE6: =IF(AND(G6>60000,F6="Active"),"High Salary") -> High Salary
A7: EMP-006 | B7: Meena L | C7: meena.hr@company.com | D7: HR-IND | E7: 44767 | F7: Inactive | G7: ₹ 41,500 | H7: On leave | I7: =IF(AND(F7="Active", E7<DATE(2022,1,1)), "Eligible", "Not Eligible") -> Not Eligible | J7: =IF(OR(F7="Inactive",H7="Late"),"Review needed","NO need") -> Review needed | K7: =IF(RIGHT(D7,3)="IND", "India Employee", "Overseas") -> India Employee | L7: =LEFT(D7, FIND("-", D7) - 1) -> HR | M7: =LEFT(C7,FIND("@company.com",C7)-1) -> meena.hr | N7: =LEFT(A7,3) -> EMP | O7: =RIGHT(D7,3) -> IND | P7: =RIGHT(D7,FIND("-",D7)) -> IND | R7: =RIGHT(A7,3) -> 006 | S7: =LOWER(CONCATENATE(B7,".",L7,"@company.com")) -> meena l.hr@company.com | V7: =_xlfn.CONCAT(A7,"|",D7) -> EMP-006|HR-IND | W7: =_xlfn.TEXTJOIN("-",TRUE,A7,B7,F7) -> EMP-006-Meena L-Inactive | Z7: =_xlfn.TEXTJOIN("/",TRUE,L7,O7,F7) -> HR/IND/Inactive | AB7: =TRIM(H7) -> On leave | AD7: =SUBSTITUTE(SUBSTITUTE(G7,"₹",""),",","")*1 -> 41500 | AE7: =IF(AND(G7>60000,F7="Active"),"High Salary") -> FALSE
A10: 🟢 PART 1: LOGICAL OPERATORS (AND / OR / NOT)
A12: 1. Display "Eligible" if:
A13: Status = "Active" AND
A14: Joining_Date before 01-01-2022
A16: 2. Display "Review Needed" if:
A17: Status = "Inactive" OR
A18: Remarks contain the word "Late"
A20: 3. Display "India Employee" if Department_Code ends with "IND", else "Overseas"
A22: 🟡 PART 2: LEFT FUNCTION
A24: 4. Extract Department name from Department_Code
A25: Example: HR-IND → HR
A27: 5. Extract first 3 characters from Emp_ID
... A74: 14. Remove extra spaces from Remarks column
A76: 15. Count how many employees have Remarks = "Good performer" | D76: =COUNTIF(AB2:AB7,"Good performer") -> 1
A77: (Hint: TRIM + COUNTIF)
A81: 🔥 INTERVIEW-LEVEL CHALLENGE
A83: 16. Extract Salary as number from Salary_Text
A85: Example: ₹ 45,000 → 45000
A87: 17. Display "High Salary" if salary > 60000 AND Status = Active

Sheet lookup
A1: Emp_ID | B1: Full_Name | C1: Department | D1: Location | E1: Join_Date | F1: Salary
A2: E101 | B2: Arun Kumar | C2: HR | D2: Chennai | E2: 43805 | F2: 28000 | I2: VLOOKUP
A3: E102 | B3: Divya R | C3: IT | D3: Bangalore | E3: 25/03/2021 | F3: 45000
A4: E103 | B4: Suresh M | C4: Finance | D4: Chennai | E4: 44105 | F4: 38000 | I4: E106 | J4: =VLOOKUP(I4,A2:F9,6,FALSE) -> 26000
A5: E104 | B5: Kavya P | C5: IT | D5: Hyderabad | E5: 19/08/2022 | F5: 52000 | I5: E102 | J5: =VLOOKUP(I5,A3:F10,6,FALSE) -> 45000
A6: E105 | B6: Manoj S | C6: Sales | D6: Mumbai | E6: 43227 | F6: 30000 | I6: E107 | J6: =VLOOKUP(I6,A4:F11,6,FALSE) -> 41000
A7: E106 | B7: Priya K | C7: HR | D7: Chennai | E7: 15/02/2023 | F7: 26000 | I7: E104 | J7: =VLOOKUP(I7,A5:F12,6,FALSE) -> 52000
A8: E107 | B8: Ramesh N | C8: Finance | D8: Pune | E8: 43780 | F8: 41000 | I8: E109 | J8: =VLOOKUP(I8,A6:F13,6,FALSE) -> #N/A
A9: E108 | B9: Sneha L | C9: Sales | D9: Bangalore | E9: 30/09/2021 | F9: 35000
I14: HLOOKUP
A16: Emp_ID | B16: E101 | C16: E102 | D16: E103 | E16: E104 | F16: E105 | G16: E106 | I16: Arun | J16: =HLOOKUP(I16,$B$17:$G$21,2,FALSE) -> HR
A17: Name | B17: Arun | C17: Divya | D17: Suresh | E17: Kavya | F17: Manoj | G17: Priya | I17: Divya | J17: =HLOOKUP(I17,$B$17:$G$21,2,FALSE) -> IT
A18: Department | B18: HR | C18: IT | D18: Finance | E18: IT | F18: Sales | G18: HR | I18: Suresh | J18: =HLOOKUP(I18,B17:G21,3,FALSE) -> Chennai
A19: Location | B19: Chennai | C19: Bangalore | D19: Chennai | E19: Hyderabad | F19: Mumbai | G19: Chennai | I19: Kavya | J19: =HLOOKUP(I19,B17:G21,2,FALSE) -> IT
A20: Salary | B20: 28000 | C20: 45000 | D20: 38000 | E20: 52000 | F20: 30000 | G20: 26000 | I20: Manoj | J20: =HLOOKUP(I20,$B$17:$G$21,2,FALSE) -> Sales
A21: Join_Year | B21: 2019 | C21: 2021 | D21: 2020 | E21: 2022 | F21: 2018 | G21: 2023 | I21: Priya | J21: =HLOOKUP(I21,$B$17:$G$21,2,FALSE) -> HR
I24: XLOOKUP
A26: Emp_ID | B26: Full_Name | C26: Dept_Code | D26: Location | E26: Join_Date | F26: Salary | J26: =_xlfn.XLOOKUP(B27,B27:B34,F27:F34) -> 28000 | L26: dpt | M26: loc
A27: E101 | B27: Arun Kumar | C27: HR | D27: Chennai | E27: 43805 | F27: 28000 | I27: Chennai | J27: =_xlfn.XLOOKUP(I27,D27:D34,B27:B34,"NOT FOUND") -> Arun Kumar | K27: Priya K | L27: {=_xlfn.XLOOKUP(K27,B27:B34,C27:D34)} -> HR | M27: Chennai
A28: E102 | B28: Divya R | C28: IT | D28: Bangalore | E28: 25/03/2021 | F28: 45000 | I28: Chennai | J28: =_xlfn.XLOOKUP(I28,D28:D35,B28:B35,"NOT FOUND") -> Suresh M | K28: Ramesh N | L28: {=_xlfn.XLOOKUP(K28,B28:B35,C28:D35)} -> FIN | M28: Pune
A29: E103 | B29: Suresh M | C29: FIN | D29: Chennai | E29: 44105 | F29: 38000 | I29: Hyderabad | J29: =_xlfn.XLOOKUP(I29,D29:D36,B29:B36,"NOT FOUND") -> Kavya P | K29: Sneha L | L29: {=_xlfn.XLOOKUP(K29,B29:B36,C29:D36)} -> SAL | M29: Bangalore
A30: E104 | B30: Kavya P | C30: IT | D30: Hyderabad | E30: 19/08/2022 | F30: 52000 | I30: Chennai | J30: =_xlfn.XLOOKUP(I30,D30:D37,B30:B37,"NOT FOUND") -> Priya K
A31: E105 | B31: Manoj S | C31: SAL | D31: Mumbai | E31: 43227 | F31: 30000
A32: E106 | B32: Priya K | C32: HR | D32: Chennai | E32: 15/02/2023 | F32: 26000
A33: E107 | B33: Ramesh N | C33: FIN | D33: Pune | E33: 43780 | F33: 41000
A34: E108 | B34: Sneha L | C34: SAL | D34: Bangalore | E34: 30/09/2021 | F34: 35000

Sheet TASK 1 LOOKUP
A1: Product_ID | B1: Available_Stock | C1: Price | G1: create a formula that returns the price when product id id typed in a cell
A2: P101 | B2: 50 | C2: 1200
A3: P102 | B3: 30 | C3: 850 | F3: vlookup | H3: P107 | I3: =VLOOKUP(H3,A2:C6,3,FALSE) -> #N/A
A4: P103 | B4: 75 | C4: 1500 | H4: P104 | I4: =VLOOKUP(H4,A2:C7,3,FALSE) -> 999
A5: P104 | B5: 20 | C5: 999
A6: P105 | B6: 60 | C6: 450
F7: xlookup | H7: P103 | I7: =_xlfn.XLOOKUP(H7,A2:A6,C2:C6,"not found",0) -> 1500
H8: P102 | I8: =_xlfn.XLOOKUP(H8,A2:A6,B2:B6) -> 30 | J8: returns available stock
H9: P109 | I9: =_xlfn.XLOOKUP(H9,A2:A6,C2:C6,"not found") -> not found
H10: P10 | I10: =_xlfn.XLOOKUP(H10&"*",A2:A6,C2:C6,"VALUE NOT FOUND",2) -> 1200
I11: =_xlfn.XLOOKUP(H11&"*",A3:A7,C3:C7,"VALUE NOT FOUND",2) -> 850
I12: =_xlfn.XLOOKUP(H12&"*",A4:A8,C4:C8,"VALUE NOT FOUND",2) -> 1500
I13: =_xlfn.XLOOKUP(H13&"*",A5:A9,C5:C9,"VALUE NOT FOUND",2) -> 999
I14: =_xlfn.XLOOKUP(H14&"*",A6:A10,C6:C10,"VALUE NOT FOUND",2) -> 450

Sheet TASK 2 LOOKUP
A1: Min_Quantity | B1: Unit_Price | F1: You must return the correct unit price for any entered quantity (even numbers are not in the list)
A2: 1 | B2: 100
A3: 10 | B3: 95 | F3: 1 | G3: =_xlfn.XLOOKUP(F3,A2:A6,B2:B6,"VALUE NOT FOUND/NOT IN THE DATA",0) -> 100
A4: 25 | B4: 90 | F4: 10 | G4: =_xlfn.XLOOKUP(F4,A2:A7,B2:B7,"VALUE NOT FOUND/NOT IN THE DATA",0) -> 95
A5: 50 | B5: 85 | F5: 20 | G5: =_xlfn.XLOOKUP(F5,A2:A8,B2:B8,"VALUE NOT FOUND/NOT IN THE DATA",0) -> VALUE NOT FOUND/NOT IN THE DATA
A6: 100 | B6: 80 | F6: 30 | G6: =_xlfn.XLOOKUP(F6,A2:A9,B2:B9,"VALUE NOT FOUND/NOT IN THE DATA",0) -> VALUE NOT FOUND/NOT IN THE DATA
F7: 40 | G7: =_xlfn.XLOOKUP(F7,A2:A10,B2:B10,"VALUE NOT FOUND/NOT IN THE DATA",0) -> VALUE NOT FOUND/NOT IN THE DATA

Sheet TASK 3 LOOKUP
A1: Employee_ID | B1: First_Name | C1: Last_Name
A2: E001 | B2: Janani | C2: Kumar | H2: TASK 1
A3: E002 | B3: Rahul | C3: Mehta | I3: 1,YOU HAVE ONE TABLE WITH EMPLOYEE ID,LAST ANME,FIRST NAME
A4: E003 | B4: Sneha | C4: Iyer | I4: 2, ON THE PAY REPORT ,ONLY EMPLOYEE ID AND PAY ARE SHOWN
A5: E004 | B5: Arjun | C5: Rao | I5: 3, YOU MUST RETUEN FIRST NAME AND LAST NAME
A6: E005 | B6: Priya | C6: Sharma

Sheet TASK 3.1 
A1: Employee_ID | B1: Pay | C1: First_Name | D1: Last_Name
A2: E003 | B2: 45000 | C2: {=_xlfn.XLOOKUP(A2,'TASK 3 LOOKUP'!A2:A6,'TASK 3 LOOKUP'!B2:C6,"NA")} -> Sneha | D2: Iyer | H2: TASK 1
A3: E001 | B3: 52000 | C3: {=_xlfn.XLOOKUP(A3,'TASK 3 LOOKUP'!A2:A7,'TASK 3 LOOKUP'!B2:C7,"NA")} -> Janani | D3: Kumar | I3: 1,YOU HAVE ONE TABLE WITH EMPLOYEE ID,LAST ANME,FIRST NAME
A4: E005 | B4: 48000 | C4: {=_xlfn.XLOOKUP(A4,'TASK 3 LOOKUP'!A4:A8,'TASK 3 LOOKUP'!B4:C8,"NA")} -> Priya | D4: Sharma | I4: 2, ON THE PAY REPORT ,ONLY EMPLOYEE ID AND PAY ARE SHOWN
I5: 3, YOU MUST RETUEN FIRST NAME AND LAST NAME

Sheet TASK 4 
A1: Employee_ID | B1: First_Name | C1: Last_Name
A2: E001 | B2: Janani | C2: Kumar
A3: E002 | B3: Rahul | C3: Mehta
A4: E003 | B4: Sneha | C4: Iyer
A5: E004 | B5: Arjun | C5: Rao
A6: E005 | B6: Priya | C6: Sharma

Sheet TASK 4.1 REF DATA
A1: Employee_ID | B1: City
A2: E001 | B2: Chennai
A3: E002 | B3: Bangalore
A4: E003 | B4: Coimbatore
A5: E004 | B5: Hyderabad
A6: E005 | B6: Pune

Sheet TASK 4 FINAL DATA 
A1: Employee_ID | B1: Pay | C1: Last_Name | D1: City
A2: E003 | B2: 45000 | C2: =_xlfn.XLOOKUP(A2,'TASK 4 '!A2:A6,'TASK 4 '!C2:C6," ") -> Iyer | D2: =_xlfn.XLOOKUP(A2,'TASK 4.1 REF DATA'!$A$2:$A$6,'TASK 4.1 REF DATA'!B2:B6,"NO VALUE") -> Coimbatore | F2: TASK 4
A3: E001 | B3: 52000 | C3: =_xlfn.XLOOKUP(A3,'TASK 4 '!A2:A7,'TASK 4 '!C2:C7," ") -> Kumar | D3: =_xlfn.XLOOKUP(A3,'TASK 4.1 REF DATA'!$A$2:$A$6,'TASK 4.1 REF DATA'!B3:B7,"NO VALUE") -> Bangalore | F3: 1 | G3: THE PAY REPORT CONTAINS EMPLOYEE ID AND PAY ONLY.YOU MUST RETURN LAST NAME AND CITY USING:
A4: E005 | B4: 48000 | C4: =_xlfn.XLOOKUP(A4,'TASK 4 '!A4:A8,'TASK 4 '!C4:C8," ") -> Sharma | D4: =_xlfn.XLOOKUP('TASK 4 FINAL DATA '!A4,'TASK 4.1 REF DATA'!A2:A6,'TASK 4.1 REF DATA'!B2:B6," ") -> Pune | G4: i,RAW DATA EXTRACT #1 (GIVES LAST NAME & FIRST NAME)
G5: ii, RAW DATA EXTRACT #2(GIVES EMPLOYEE ID & CITY)

Sheet TASK 5
A1: Pay_Min | B1: Pay_Max | C1: Pay_Band
A2: 0 | B2: 20000 | C2: Band A
A3: 20001 | B3: 40000 | C3: Band B
A4: 40001 | B4: 60000 | C4: Band C
A5: 60001 | B5: 80000 | C5: Band D

Sheet TASK 5.1
A1: Employee_ID | B1: Salary | C1: Pay_Band
A2: E001 | B2: 52000 | C2: =_xlfn.XLOOKUP(B2, 'TASK 5'!A:A, 'TASK 5'!C:C, , -1) -> Band C | E2: =_xlfn.XLOOKUP(B2,'TASK 5'!$A$2:$A$5,'TASK 5'!$C$2:$C$5,"NOT FOUND",-1) -> Band C
A3: E002 | B3: 38000 | C3: =_xlfn.XLOOKUP(B3, 'TASK 5'!A:A, 'TASK 5'!C:C, , -1) -> Band B | E3: =_xlfn.XLOOKUP(B3,'TASK 5'!$A$2:$A$5,'TASK 5'!$C$2:$C$5,"NOT FOUND",-1) -> Band B
A4: E003 | B4: 45000 | C4: =_xlfn.XLOOKUP(B4, 'TASK 5'!A:A, 'TASK 5'!C:C, , -1) -> Band C | E4: =_xlfn.XLOOKUP(B4,'TASK 5'!$A$2:$A$5,'TASK 5'!$C$2:$C$5,"NOT FOUND",-1) -> Band C
A5: E004 | B5: 65000 | C5: =_xlfn.XLOOKUP(B5, 'TASK 5'!A:A, 'TASK 5'!C:C, , -1) -> Band D | E5: =_xlfn.XLOOKUP(B5,'TASK 5'!$A$2:$A$5,'TASK 5'!$C$2:$C$5,"NOT FOUND",-1) -> Band D
A6: E005 | B6: 18000 | C6: =_xlfn.XLOOKUP(B6, 'TASK 5'!A:A, 'TASK 5'!C:C, , -1) -> Band A | E6: =_xlfn.XLOOKUP(B6,'TASK 5'!$A$2:$A$5,'TASK 5'!$C$2:$C$5,"NOT FOUND",-1) -> Band A

Sheet index match
A1: Emp_ID | B1: Name | C1: Department | D1: Salary
A2: 101 | B2: Arun | C2: HR | D2: 25000 | I2: Find row position of Emp_ID = 103 | O2: =MATCH(A4,A2:A6,0) -> 3
A3: 102 | B3: Divya | C3: IT | D3: 32000
A4: 103 | B4: Karthik | C4: Finance | D4: 28000 | I4: Get Name of Emp_ID = 104 | O4: =INDEX(A2:D6,4,2) -> Meena
A5: 104 | B5: Meena | C5: IT | D5: 35000
A6: 105 | B6: Rahul | C6: HR | D6: 27000 | I6: Get Salary of Emp_ID = 102 | O6: =INDEX(A2:D6,2,4) -> 32000
I8: Get Department of Emp_ID typed in cell F2 | O8: =INDEX(A2:D6,5,3) -> HR
J10: 105
C13: Marks (for 2-Way Lookup)
I21: Get marks of: Student name in A24 Subject name in B26 | O21: =INDEX(A23:D26,2,1) -> Bala
A22: Student | B22: Math | C22: Science | D22: English
A23: Anu | B23: 78 | C23: 82 | D23: 75 | O23: =INDEX(A22:D26,1,2) -> Math
A24: Bala | B24: 85 | C24: 79 | D24: 88
A25: Chitra | B25: 90 | C25: 91 | D25: 89
A26: Deepak | B26: 72 | C26: 68 | D26: 70 | I26: Find highest salary using INDEX Return Name of employee with salary = 35000 | O26: =INDEX(A2:D6,MATCH(MAX(D2:D6),D2:D6,0),4) -> 35000
O27: =INDEX(A2:D6,MATCH(35000,D2:D6,0),2) -> Meena

Sheet SORT-SORTBY
K2: SORT
A3: Emp_ID | B3: Name | C3: Department | D3: Salary | E3: Joining_Date
A4: E101 | B4: Arun | C4: IT | D4: 35000 | E4: 44536 | F4: =DATE( VALUE(RIGHT(E4,4)), VALUE(MID(E4,4,2)), VALUE(LEFT(E4,2)) ) -> 963889 | H4: Sort by Salary (Ascending) | M4: {=_xlfn._xlws.SORT(A4:E10,4,1)} -> E105 | N4: Sanjay | O4: HR | P4: 26000 | Q4: 44323
A5: E102 | B5: Priya | C5: HR | D5: 28000 | E5: 25/03/2020 | F5: =DATE( VALUE(RIGHT(E5,4)), VALUE(MID(E5,4,2)), VALUE(LEFT(E5,2)) ) -> 43915 | M5: E102 | N5: Priya | O5: HR | P5: 28000 | Q5: 25/03/2020
A6: E103 | B6: Karthik | C6: Finance | D6: 42000 | E6: 43739 | F6: =DATE( VALUE(RIGHT(E6,4)), VALUE(MID(E6,4,2)), VALUE(LEFT(E6,2)) ) -> 672880 | M6: E104 | N6: Divya | O6: IT | P6: 30000 | Q6: 18/11/2022
A7: E104 | B7: Divya | C7: IT | D7: 30000 | E7: 18/11/2022 | F7: =DATE( VALUE(RIGHT(E7,4)), VALUE(MID(E7,4,2)), VALUE(LEFT(E7,2)) ) -> 44883 | M7: E101 | N7: Arun | O7: IT | P7: 35000 | Q7: 44536
A8: E105 | B8: Sanjay | C8: HR | D8: 26000 | E8: 44323 | F8: =DATE( VALUE(RIGHT(E8,4)), VALUE(MID(E8,4,2)), VALUE(LEFT(E8,2)) ) -> 885697 | M8: E106 | N8: Meena | O8: Finance | P8: 39000 | Q8: 14/09/2020
A9: E106 | B9: Meena | C9: Finance | D9: 39000 | E9: 14/09/2020 | F9: =DATE( VALUE(RIGHT(E9,4)), VALUE(MID(E9,4,2)), VALUE(LEFT(E9,2)) ) -> 44088 | M9: E103 | N9: Karthik | O9: Finance | P9: 42000 | Q9: 43739
A10: E107 | B10: Rahul | C10: IT | D10: 45000 | E10: 43133 | F10: =DATE( VALUE(RIGHT(E10,4)), VALUE(MID(E10,4,2)), VALUE(LEFT(E10,2)) ) -> 451361 | M10: E107 | N10: Rahul | O10: IT | P10: 45000 | Q10: 43133
H12: Sort by Salary (Descending) | M12: {=_xlfn._xlws.SORT(A4:E10,4,-1)} -> E107 | N12: Rahul | O12: IT | P12: 45000 | Q12: 43133
M13: E103 | N13: Karthik | O13: Finance | P13: 42000 | Q13: 43739
M14: E106 | N14: Meena | O14: Finance | P14: 39000 | Q14: 14/09/2020
M15: E101 | N15: Arun | O15: IT | P15: 35000 | Q15: 44536
M16: E104 | N16: Divya | O16: IT | P16: 30000 | Q16: 18/11/2022
M17: E102 | N17: Priya | O17: HR | P17: 28000 | Q17: 25/03/2020
M18: E105 | N18: Sanjay | O18: HR | P18: 26000 | Q18: 44323
E19: =ISNUMBER(F4) -> TRUE
H20: Sort by Name (A → Z) | M20: {=_xlfn._xlws.SORT(A4:E10,2,1)} -> E101 | N20: Arun | O20: IT | P20: 35000 | Q20: 44536
M21: E104 | N21: Divya | O21: IT | P21: 30000 | Q21: 18/11/2022
M22: E103 | N22: Karthik | O22: Finance | P22: 42000 | Q22: 43739
B23: {=_xlfn.SORTBY(A4:E10, F4:F10, 1)} -> E102 | C23: Priya | D23: HR | E23: 28000 | F23: 25/03/2020 | M23: E106 | N23: Meena | O23: Finance | P23: 39000 | Q23: 14/09/2020
B24: E106 | C24: Meena | D24: Finance | E24: 39000 | F24: 14/09/2020 | M24: E102 | N24: Priya | O24: HR | P24: 28000 | Q24: 25/03/2020
B25: E104 | C25: Divya | D25: IT | E25: 30000 | F25: 18/11/2022 | M25: E107 | N25: Rahul | O25: IT | P25: 45000 | Q25: 43133
B26: E107 | C26: Rahul | D26: IT | E26: 45000 | F26: 43133 | M26: E105 | N26: Sanjay | O26: HR | P26: 26000 | Q26: 44323
B27: E103 | C27: Karthik | D27: Finance | E27: 42000 | F27: 43739
B28: E105 | C28: Sanjay | D28: HR | E28: 26000 | F28: 44323
B29: E101 | C29: Arun | D29: IT | E29: 35000 | F29: 44536 | K29: SORT BY
H31: Sort employees by Salary (High → Low) | M31: {=_xlfn.SORTBY(A4:E10,D4:D10,-1)} -> E107 | N31: Rahul | O31: IT | P31: 45000 | Q31: 43133
M32: E103 | N32: Karthik | O32: Finance | P32: 42000 | Q32: 43739
M33: E106 | N33: Meena | O33: Finance | P33: 39000 | Q33: 14/09/2020
M34: E101 | N34: Arun | O34: IT | P34: 35000 | Q34: 44536
M35: E104 | N35: Divya | O35: IT | P35: 30000 | Q35: 18/11/2022
M36: E102 | N36: Priya | O36: HR | P36: 28000 | Q36: 25/03/2020
M37: E105 | N37: Sanjay | O37: HR | P37: 26000 | Q37: 44323
H40: Sort by Department (A–Z) then Salary (High → Low) | M40: {=_xlfn.SORTBY(A4:E10,C4:C10,1)} -> E103 | N40: Karthik | O40: Finance | P40: 42000 | Q40: 43739
M41: E106 | N41: Meena | O41: Finance | P41: 39000 | Q41: 14/09/2020
M42: E102 | N42: Priya | O42: HR | P42: 28000 | Q42: 25/03/2020
M43: E105 | N43: Sanjay | O43: HR | P43: 26000 | Q43: 44323
M44: E101 | N44: Arun | O44: IT | P44: 35000 | Q44: 44536
M45: E104 | N45: Divya | O45: IT | P45: 30000 | Q45: 18/11/2022
...
